<?xml version="1.0" ?>
<robot name="mini_cheetah" xmlns:xacro="http://ros.org/wiki/xacro">
<!-- center of mass  0 0.0 0.0        -->
    <!--!!!!!!!!!!!!!!!!!!BODY!!!!!!!!!!!!!!!!!!!!!!!!!!!!!!!-->
    <link name="body">
        <inertial>
            <mass value="1258.31807296e-3"/>
            <origin xyz="-0.43736695e-2 -0.07737584e-2 0.08102850e-2"/>
      <inertia
        ixx="24223.93682550e-7"
        ixy="-907.91818721e-7"
        ixz="43.46649371e-7"
        iyy="186672.18928423e-7"
        iyz="-2.54822989e-7"
        izz="206033.06774587e-7" />
                </inertial>
        <visual>
            <geometry>
                <mesh filename="meshes/solo_12_base.obj"/>
            </geometry>
            <origin rpy="1.5707963267948966 0.0 0.0" xyz="0.0 0.0 0.0"/>
            <!-- <material
                name="base_link">
            <color 
                rgba="1 0 0 0.83" />
            </material> -->
        </visual>
    </link>

<!--!!!!!!!!!!!! Front Left Leg !!!!!!!!!!!!!!!!!!!!!!!!!!!!!!!!!!!!-->
    <joint name="torso_to_abduct_fl_j" type="continuous">
        <axis xyz="1 0 0"/>
        <origin rpy="0 0 0" xyz="0.2141 0.0875 0.0 "/> 
        <parent link="body"/>
        <child link="abduct_fl"/>
        <limit effort="18" lower="-1.6" upper="1.6" velocity="40"/>
    </joint>
    <link name="abduct_fl">
        <inertial> 
            <mass value="143.68024490e-3"/>
            <origin xyz="-10.98765927e-2 -0.46677473e-2 0.00136777e-2"/>
      <inertia
        ixx="275.90047445e-7"
        ixy="-254.50227212e-7"
        ixz="0.71210009e-7"
        iyy="3863.78054959e-7"
        iyz="0.03414311e-7"
        izz="3839.41857894e-7" />
        </inertial>
        <visual>
            <geometry>
                <mesh filename="meshes/solo12_hip_fe_fl.obj"/>
            </geometry>
            <origin rpy="1.5707963267948966 0. 0." xyz="0 0 0.0"/>
        </visual>
        <!--
        <collision>
            <geometry>
                <cylinder length ="0.02" radius = "0.0475"/>
            </geometry>
            <origin rpy="0 1.5708 -1.5708" xyz="-0.055 0.0 0.0"/>
        </collision>
        <collision>
            <geometry>
                <cylinder length ="0.06" radius = "0.0475"/>
            </geometry>
            <origin rpy="1.5708 0.0 0.0" xyz="0.0 0.0 0.0"/>
        </collision>
        -->
    </link>

    <joint name="abduct_fl_to_thigh_fl_j" type="continuous">
        <axis xyz="0 -1 0"/>
        <origin rpy="0.0 0.0 0.0" xyz="-19.65e-3 14e-3 0"/>
        <parent link="abduct_fl"/>
        <child link="thigh_fl"/>
        <limit effort="18" lower="-2.6" upper="2.6" velocity="40"/>
    </joint>
    <link name="thigh_fl">
        <inertial>
            <mass value="144.14222037e-3"/>
            <origin xyz="0.00174095e-2 1.57310796e-2 -6.91454765e-2"/>
      <inertia
        ixx="3814.98952871e-7"
        ixy="-0.07326249e-7"
        ixz="-0.91813078e-7"
        iyy="3789.60402317e-7"
        iyz="492.68237352e-7"
        izz="325.88466892e-7" />
        </inertial>
        <visual>
            <geometry>
                <mesh filename="meshes/solo12_upper_leg_left_side.obj"/>
            </geometry>
            <origin rpy="1.5707963267948966 0 0" xyz="0 0 0.0"/>
        </visual>
        <!--
        <collision>
            <geometry>
                <cylinder length ="0.21" radius = "0.025"/>
            </geometry>
            <origin rpy="0.0 0.0 0.0" xyz="0.0 0.0 -0.105"/>
        </collision>
        -->
    </link>

    <joint name="thigh_fl_to_knee_fl_j" type="continuous">
        <axis xyz="0 -1 0"/>
        <origin rpy="0.0 0 0.0" xyz="0.0 37e-3 -0.16"/>
        <parent link="thigh_fl"/>
        <child link="shank_fl"/>
        <limit effort="26" lower="-2.6" upper="2.6" velocity="26"/>
    </joint>
    <link name="shank_fl">
        <inertial>
            <mass value="23.48772094e-3"/>
            <origin xyz="0 0.75190156 -2.69034785e-2"/>
      <inertia
        ixx="128.39137653e-7"
        ixy="0.00000524e-7"
        ixz="-0.00014698e-7"
        iyy="134.04180965e-7"
        iyz="-9.36618856e-7"
        izz="12.83208435e-7" />
               </inertial>
        <visual>
            <geometry>
                <mesh filename="meshes/solo12_lower_leg_H.obj" scale="1 1 1"/>
            </geometry>
            <origin rpy="0 0 3.141592653589793" xyz="0.0 0 0 "/>
        </visual>
    </link>

    <joint name="lower_leg_joint1_fl" type="fixed">
        <axis xyz="0 -1 0"/>
        <origin rpy="0.0 0 0.0" xyz="0.0 7.95e-3 -0.0725"/>
        <parent link="shank_fl"/>
        <child link="lower_leg_center_fl"/>
    </joint>
    <link name="lower_leg_center_fl">
        <inertial>
            <mass value="1e-3"/>
            <origin xyz="0 0 -7.5e-3"/>
        <inertia
            ixx="0"
            ixy="0"
            ixz="0"
            iyy="0"
            iyz="0"
            izz="0" />
        </inertial>
        <visual>
            <geometry>
                <box size="10e-3 10e-3 14e-3" />
            </geometry>
            <origin rpy="0 0 0.0" xyz="0.0 0 -7.5e-3"/>
        </visual>
    </link>
    <joint name="lower_leg_joint2_fl" type="fixed">
        <axis xyz="0 -1 0"/>
        <origin rpy="0.0 0 0.0" xyz="0.0 0 -0.014"/>
        <parent link="lower_leg_center_fl"/>
        <child link="lower_leg_L_fl"/>
    </joint>
    <link name="lower_leg_L_fl">
        <inertial>
            <mass value="14.20602001e-3"/>
            <origin xyz="0 0 -5.34282905e-2"/>
        <inertia
            ixx="91.73083151e-7"
            ixy="0"
            ixz="0"
            iyy="94.50145857e-7"
            iyz="0"
            izz="4.91707136e-7" />
        </inertial>
        <visual>
            <geometry>
                <mesh filename="meshes/solo12_lower_leg_L.obj" scale="1 1 1"/>
            </geometry>
            <origin rpy="0 0 0.0" xyz="0.0 0 7.5e-3"/>
        </visual>
    </link>
    
    <!--!!!!!!!!!!!! Front Right Leg !!!!!!!!!!!!!!!!!!!!!!!!!!!!!!!!!!!!-->
    <joint name="torso_to_abduct_fr_j" type="continuous">
        <axis xyz="1 0 0"/>
        <origin rpy="0 0 0" xyz="0.2141 -0.0875 0.0"/>
        <parent link="body"/>
        <child link="abduct_fr"/>
        <limit effort="18" lower="-1.6" upper="1.6" velocity="40"/>
    </joint>
    <link name="abduct_fr">
        <inertial>
            <mass value="143.68024490e-3"/>
            <origin xyz="-11.05511528e-2 0.46677473e-2 -0.00136777e-2"/>
      <inertia
        ixx="275.90047445e-7"
        ixy="249.97824669e-7"
        ixz="-0.69884355e-7"
        iyy="4013.39961851e-7"
        iyz="0.03414311e-7"
        izz="3989.03764786e-7" />
        </inertial>
        <visual>
            <geometry>
                <mesh filename="meshes/solo12_hip_fe_fr.obj"/>
            </geometry>
            <origin rpy="1.5707963267948966 0.0 0" xyz="0 0.0 0.0"/>
        </visual>
        <!--
        <collision>
            <geometry>
                <cylinder length ="0.02" radius = "0.0475"/>
            </geometry>
            <origin rpy="3.141592 1.5708 1.5708" xyz="-0.055 0 0"/>
        </collision>
        <collision>
            <geometry>
                <cylinder length ="0.06" radius = "0.0475"/>
            </geometry>
            <origin rpy="1.5708 0.0 0.0" xyz="-0.055 0 0"/>
        </collision>
        -->
    </link>

    <joint name="abduct_fr_to_thigh_fr_j" type="continuous">
        <axis xyz="0 -1 0"/>
        <origin rpy="0.0 0.0 0.0" xyz="-19.65e-3 -14e-3 0"/>
        <parent link="abduct_fr"/>
        <child link="thigh_fr"/>
        <limit effort="18" lower="-2.6" upper="2.6" velocity="40"/>
    </joint>
    <link name="thigh_fr">
        <inertial>
            <mass value="144.14222037e-3"/>
            <origin xyz="-0.00174095e-2 -1.57310796e-2 -6.91454765e-2"/>
      <inertia
        ixx="3814.98952871e-7"
        ixy="-0.07326249e-7"
        ixz="0.91813078e-7"
        iyy="3789.60402317e-7"
        iyz="-492.68237352e-7"
        izz="325.88466892e-7" />
        </inertial>
        <visual>
            <geometry>
                <mesh filename="meshes/solo12_upper_leg_right_side.obj"/>
            </geometry>
            <origin rpy="1.5707963267948966 0 0" xyz="0.0 0.0 0.0"/>
        </visual>
        <!--
        <collision>
            <geometry>
                <cylinder length ="0.21" radius = "0.025"/>
            </geometry>
            <origin rpy="0.0 0.0 0.0" xyz="0.0 0.0 -0.105"/>
        </collision>
        -->
    </link>

    <joint name="thigh_fr_to_knee_fr_j" type="continuous">
        <axis xyz="0 -1 0"/>
        <origin rpy="0.0 0 0.0" xyz="0.0 -37e-3 -0.16"/>
        <parent link="thigh_fr"/>
        <child link="shank_fr"/>
        <limit effort="26" lower="-2.6" upper="2.6" velocity="26"/>
    </joint>
    <link name="shank_fr">
        <inertial>
            <mass value="44.08831168e-3"/>
            <origin xyz="0 -0.44121055e-2 -5.66875318e-2"/>
      <inertia
        ixx="1484.45244047e-7"
        ixy="-0.00000055e-7"
        ixz="0.00000017e-7"
        iyy="1481.80426492e-7"
        iyz="-88.42737375e-7"
        izz="39.73914276e-7" />
               </inertial>
        <visual>
            <geometry>
                <mesh filename="meshes/solo12_lower_leg_v2_right_side.obj"/>
            </geometry>
            <origin rpy="1.5707963267948966 0 0.0" xyz="0.0 0.0 0.0"/>
        </visual>
        <!--
        <collision>
            <geometry>
                <cylinder length ="0.19" radius = "0.015"/>
            </geometry>
            <origin rpy="0.0 3.141592 0.0" xyz="0.0 0.0 -0.095"/>
        </collision>
        <collision>
            <geometry>
                <sphere radius = "0.0175"/>
            </geometry>
            <origin rpy="0.0 3.141592 0" xyz="0.0 0.0 -0.195"/>
        </collision>
        -->
    </link>

<!-- -0.19 0.049    -0.2141 0.0875 -->
    <!--!!!!!!!!!!!! Hind Left Leg !!!!!!!!!!!!!!!!!!!!!!!!!!!!!!!!!!!!-->
    <joint name="torso_to_abduct_hl_j" type="continuous">
        <axis xyz="1 0 0"/>
        <origin rpy="0 0 0" xyz="-0.2141 0.0875 0.0"/>
        <parent link="body"/>
        <child link="abduct_hl"/>
        <limit effort="18" lower="-1.6" upper="1.6" velocity="40"/>
    </joint>
    <link name="abduct_hl">
        <inertial>
            <mass value="143.68024490e-3"/>
            <origin xyz="11.05511528e-2 -0.46677473e-2 -0.00136777e-2"/>
      <inertia
        ixx="275.90047445e-7"
        ixy="249.97824669e-7"
        ixz="0.69884355e-7"
        iyy="4013.39961851e-7"
        iyz="-0.03414311e-7"
        izz="3989.03764786e-7" />
        </inertial>
        <visual>
            <geometry>
                <mesh filename="meshes/solo12_hip_fe_hl.obj"/>
            </geometry>
            <origin rpy="1.5707963267948966 0.0 0" xyz="0 0.0 0.0"/>
        </visual>
        <!--
        <collision>
            <geometry>
                <cylinder length ="0.02" radius = "0.0475"/>
            </geometry>
            <origin rpy="3.141592 1.5708 -1.5708" xyz="0.055 0 0"/>
        </collision>
        <collision>
            <geometry>
                <cylinder length ="0.06" radius = "0.0475"/>
            </geometry>
            <origin rpy="1.5708 0.0 0.0" xyz="0.0 0.0 0.0"/>
        </collision>
        -->
    </link>

<!-- 0.0 0.062 0.00    19.65e-3 14e-3 0 -->
    <joint name="abduct_hl_to_thigh_hl_j" type="continuous">
        <axis xyz="0 -1 0"/>
        <origin rpy="0.0 0.0 0.0" xyz="19.65e-3 14e-3 0 "/>
        <parent link="abduct_hl"/>
        <child link="thigh_hl"/>
        <limit effort="18" lower="-2.6" upper="2.6" velocity="40"/>
    </joint>
    <link name="thigh_hl">
        <inertial>
            <mass value="144.14222037e-3"/>
            <origin xyz="0.00174095e-2 1.57310796e-2 -6.91454765e-2"/>
      <inertia
        ixx="3814.98952871e-7"
        ixy="-0.07326249e-7"
        ixz="-0.91813078e-7"
        iyy="3789.60402317e-7"
        iyz="492.68237352e-7"
        izz="325.88466892e-7" />
        </inertial>
        <visual>
            <geometry>
                <mesh filename="meshes/solo12_upper_leg_left_side.obj"/>
            </geometry>
            <origin rpy="1.5707963267948966 0 0" xyz="0.0 0.0 0.0"/>
        </visual>
        <!--
        <collision>
            <geometry>
                <cylinder length ="0.21" radius = "0.025"/>
            </geometry>
            <origin rpy="0.0 0.0 0.0" xyz="0.0 0.0 -0.105"/>
        </collision>
        -->
    </link>

    <joint name="thigh_hl_to_knee_hl_j" type="continuous">
        <axis xyz="0 -1 0"/>
        <origin rpy="0.0 0 0.0" xyz="0.0 37e-3 -0.16"/>
        <parent link="thigh_hl"/>
        <child link="shank_hl"/>
        <limit effort="26" lower="-2.6" upper="2.6" velocity="26"/>
    </joint>
    <link name="shank_hl">
        <inertial>
            <mass value="44.08831168e-3"/>
            <origin xyz="0 0.44121055e-2 -5.66875318e-2"/>
      <inertia
        ixx="1484.45244047e-7"
        ixy="-0.00000055e-7"
        ixz="-0.00000017e-7"
        iyy="1481.80426492e-7"
        iyz="88.42737375e-7"
        izz="39.73914276e-7" />
               </inertial>
        <visual>
            <geometry>
                <mesh filename="meshes/solo12_lower_leg_v2_left_side.obj"/>
            </geometry>
            <origin rpy="1.5707963267948966 0 0.0" xyz="0.0 0.0 0.0"/>
        </visual>
        <!--
        <collision>
            <geometry>
                <cylinder length ="0.19" radius = "0.015"/>
            </geometry>
            <origin rpy="0.0 3.141592 0.0" xyz="0.0 0.0 -0.095"/>
        </collision>
        <collision>
            <geometry>
                <sphere radius = "0.0175"/>
            </geometry>
            <origin rpy="0.0 3.141592 0.0" xyz="0.0 0.0 -0.195"/>
        </collision>
        -->
    </link>

    <!--!!!!!!!!!!!! Hind Right Leg !!!!!!!!!!!!!!!!!!!!!!!!!!!!!!!!!!!!-->
    <joint name="torso_to_abduct_hr_j" type="continuous">
        <axis xyz="1 0 0"/>
        <origin rpy="0 0 0" xyz="-0.2141 -0.0875 0.0"/>
        <parent link="body"/>
        <child link="abduct_hr"/>
        <limit effort="18" lower="-1.6" upper="1.6" velocity="40"/>
    </joint>
    <link name="abduct_hr">
        <inertial>
            <mass value="143.68024490e-3"/>
            <origin xyz="10.98765927e-2 0.46677473e-2 0.00136777e-2"/>
      <inertia
        ixx="275.90047445e-7"
        ixy="254.50227212e-7"
        ixz="-0.71210009e-7"
        iyy="3863.78054959e-7"
        iyz="-0.03414311e-7"
        izz="3839.41857894e-7" />
        </inertial>
        <visual>
            <geometry>
                <mesh filename="meshes/solo12_hip_fe_hr.obj"/>
            </geometry>
            <origin rpy="1.5707963267948966 0.0 0" xyz="0 0.0 0.0"/>
        </visual>
        <!--
        <collision>
            <geometry>
                <cylinder length ="0.02" radius = "0.0475"/>
            </geometry>
            <origin rpy="0.0 1.5708 1.5708" xyz="0.055 0.0 0.0"/>
        </collision>
        <collision>
            <geometry>
                <cylinder length ="0.06" radius = "0.0475"/>
            </geometry>
            <origin rpy="1.5708 0.0 0.0" xyz="0.0 0.0 0.0"/>
        </collision>
        -->
    </link>

    <joint name="abduct_hr_to_thigh_hr_j" type="continuous">
        <axis xyz="0 -1 0"/>
        <origin rpy="0.0 0 0" xyz="19.65e-3 -14e-3 0"/>
        <parent link="abduct_hr"/>
        <child link="thigh_hr"/>
        <limit effort="18" lower="-2.6" upper="2.6" velocity="40"/>
    </joint>
    <link name="thigh_hr">
        <inertial>
            <mass value="144.14222037e-3"/>
            <origin xyz="-0.00174095e-2 -1.57310796e-2 -6.91454765e-2"/>
      <inertia
        ixx="3814.98952871e-7"
        ixy="-0.07326249e-7"
        ixz="0.91813078e-7"
        iyy="3789.60402317e-7"
        iyz="-492.68237352e-7"
        izz="325.88466892e-7" />
        </inertial>
        <visual>
            <geometry>
                <mesh filename="meshes/solo12_upper_leg_right_side.obj"/>
            </geometry>
            <origin rpy="1.5707963267948966 0 0" xyz="0.0 0.0 0.0"/>
        </visual>
        <!--
        <collision>
            <geometry>
                <cylinder length ="0.21" radius = "0.025"/>
            </geometry>
            <origin rpy="0.0 0.0 0.0" xyz="0.0 0.0 -0.105"/>
        </collision>
        -->
    </link>

    <joint name="thigh_hr_to_knee_hr_j" type="continuous">
        <axis xyz="0 -1 0"/>
        <origin rpy="0.0 0 0" xyz="0.0 -37e-3 -0.16"/>
        <parent link="thigh_hr"/>
        <child link="shank_hr"/>
        <limit effort="26" lower="-2.6" upper="2.6" velocity="26"/>
    </joint>
    <link name="shank_hr">
        <inertial>
            <mass value="44.08831168e-3"/>
            <origin xyz="0 -0.44121055e-2 -5.66875318e-2"/>
      <inertia
        ixx="1484.45244047e-7"
        ixy="-0.00000055e-7"
        ixz="0.00000017e-7"
        iyy="1481.80426492e-7"
        iyz="-88.42737375e-7"
        izz="39.73914276e-7" />
                </inertial>
        <visual>
            <geometry>
                <mesh filename="meshes/solo12_lower_leg_v2_right_side.obj"/>
            </geometry>
            <origin rpy="1.5707963267948966 0 0.0" xyz="0 0 0"/>
        </visual>
    </link>

    <!-- Add foot links to enable relevent computations, including better collision detection -->
    <joint name="shank_fl_to_foot_fl" type="fixed">
        <parent link="lower_leg_L_fl"/>
        <child link="LF_FOOT"/>
        <origin rpy="0.0 0.0 0.0" xyz="0.0 0 -0.08"/>
    </joint>
    <link name="LF_FOOT">
        <inertial>
            <mass value="0.005"/>
        </inertial>
        <collision>
            <geometry>
                <sphere radius = "0.018"/>
            </geometry>
            <origin rpy="0.0 0.0 0.0" xyz="0.0 0.0 0.0"/>
        </collision>
        <visual>    
            <geometry>
                <sphere radius = "0.018"/>
            </geometry>
            <origin rpy="0.0 0.0 0.0" xyz="0.0 0.0 0.0"/>
            <material>
                <color rgba="1 1 1 0.6"/>
            </material>    
        </visual>
    </link>
    
    <joint name="shank_fr_to_foot_fr" type="fixed">
        <parent link="shank_fr"/>
        <child link="RF_FOOT"/>
        <origin rpy="0.0 0.0 0.0" xyz="0.0 -7.95e-3 -0.16"/>
    </joint>
    <link name="RF_FOOT">
        <inertial>
            <mass value="0.005"/>
        </inertial>
        <collision>
            <geometry>
                <sphere radius = "0.018"/>
            </geometry>
            <origin rpy="0.0 0.0 0.0" xyz="0.0 0.0 0.0"/>
        </collision>
        <visual>
            <geometry>
                <sphere radius = "0.018"/>
            </geometry>
            <origin rpy="0.0 0.0 0.0" xyz="0.0 0.0 0.0"/>
            <material>
                <color rgba="1 1 1 0.6"/>
            </material>    
        </visual>
    </link>
    
    <joint name="shank_hl_to_foot_hl" type="fixed">
        <parent link="shank_hl"/>
        <child link="LH_FOOT"/>
        <origin rpy="0.0 0.0 0.0" xyz="0.0 7.95e-3 -0.16"/>
    </joint>
    <link name="LH_FOOT">
        <inertial>
            <mass value="0.005"/>
        </inertial>
        <collision>
            <geometry>
                <sphere radius = "0.018"/>
            </geometry>
            <origin rpy="0.0 0.0 0.0" xyz="0.0 0.0 0.0"/>
        </collision>
        <visual>
            <geometry>
                <sphere radius = "0.018"/>
            </geometry>
            <origin rpy="0.0 0.0 0.0" xyz="0.0 0.0 0.0"/>
            <material>
                <color rgba="1 1 1 0.6"/>
            </material>    
        </visual>
    </link>
    
    <joint name="shank_hr_to_foot_hr" type="fixed">
        <parent link="shank_hr"/>
        <child link="RH_FOOT"/>
        <origin rpy="0.0 0.0 0.0" xyz="0.0 -7.95e-3 -0.16"/>
    </joint>
    <link name="RH_FOOT">
        <inertial>
            <mass value="0.005"/>
        </inertial>
        <collision>
            <geometry>
                <sphere radius = "0.018"/>
            </geometry>
            <origin rpy="0.0 0.0 0.0" xyz="0.0 0.0 0.0"/>
        </collision>
        <visual>
            <geometry>
                <sphere radius = "0.018"/>
            </geometry>
            <origin rpy="0.0 0.0 0.0" xyz="0.0 0.0 0.0"/>
            <material>
                <color rgba="1 1 1 0.6"/>
            </material>    
        </visual>
    </link>

    <!-- Joint Transmissions: Tells Drake that these are actuated -->
    <transmission name="torso_to_abduct_fl_j_transmission">
        <type>transmission_interface/SimpleTransmission</type>
        <joint name="torso_to_abduct_fl_j"/>
        <actuator name="torso_to_abduct_fl_j_actuator"/>
    </transmission>
    <transmission name="abduct_fl_to_thigh_fl_j_transmission">
        <type>transmission_interface/SimpleTransmission</type>
        <joint name="abduct_fl_to_thigh_fl_j"/>
        <actuator name="abduct_fl_to_thigh_fl_j_actuator"/>
    </transmission>
    <transmission name="thigh_fl_to_knee_fl_j_transmission">
        <type>transmission_interface/SimpleTransmission</type>
        <joint name="thigh_fl_to_knee_fl_j"/>
        <actuator name="thigh_fl_to_knee_fl_j_actuator"/>
    </transmission>

    <transmission name="torso_to_abduct_fr_j_transmission">
        <type>transmission_interface/SimpleTransmission</type>
        <joint name="torso_to_abduct_fr_j"/>
        <actuator name="torso_to_abduct_fr_j_actuator"/>
    </transmission>
    <transmission name="abduct_fr_to_thigh_fr_j_transmission">
        <type>transmission_interface/SimpleTransmission</type>
        <joint name="abduct_fr_to_thigh_fr_j"/>
        <actuator name="abduct_fr_to_thigh_fr_j_actuator"/>
    </transmission>
    <transmission name="thigh_fr_to_knee_fr_j_transmission">
        <type>transmission_interface/SimpleTransmission</type>
        <joint name="thigh_fr_to_knee_fr_j"/>
        <actuator name="thigh_fr_to_knee_fr_j_actuator"/>
    </transmission>

    <transmission name="torso_to_abduct_hl_j_transmission">
        <type>transmission_interface/SimpleTransmission</type>
        <joint name="torso_to_abduct_hl_j"/>
        <actuator name="torso_to_abduct_hl_j_actuator"/>
    </transmission>
    <transmission name="abduct_hl_to_thigh_hl_j_transmission">
        <type>transmission_interface/SimpleTransmission</type>
        <joint name="abduct_hl_to_thigh_hl_j"/>
        <actuator name="abduct_hl_to_thigh_hl_j_actuator"/>
    </transmission>
    <transmission name="thigh_hl_to_knee_hl_j_transmission">
        <type>transmission_interface/SimpleTransmission</type>
        <joint name="thigh_hl_to_knee_hl_j"/>
        <actuator name="thigh_hl_to_knee_hl_j_actuator"/>
    </transmission>

    <transmission name="torso_to_abduct_hr_j_transmission">
        <type>transmission_interface/SimpleTransmission</type>
        <joint name="torso_to_abduct_hr_j"/>
        <actuator name="torso_to_abduct_hr_j_actuator"/>
    </transmission>
    <transmission name="abduct_hr_to_thigh_hr_j_transmission">
        <type>transmission_interface/SimpleTransmission</type>
        <joint name="abduct_hr_to_thigh_hr_j"/>
        <actuator name="abduct_hr_to_thigh_hr_j_actuator"/>
    </transmission>
    <transmission name="thigh_hr_to_knee_hr_j_transmission">
        <type>transmission_interface/SimpleTransmission</type>
        <joint name="thigh_hr_to_knee_hr_j"/>
        <actuator name="thigh_hr_to_knee_hr_j_actuator"/>
    </transmission>

</robot>
